#VRML_SIM V8.3.0 utf8
WorldInfo {
  contactProperties [
    ContactProperties {
      material1 "leg"
      material2 "floor"
      coulombFriction [
        5
      ]
    }
    ContactProperties {
      material1 "body"
      material2 "floor"
      coulombFriction [
        0.2
      ]
    }
  ]
}
Viewpoint {
  orientation -0.788413 -0.573516 -0.222449 0.914377
  position -5.34586 14.1875 17.0076
}
Background {
}
DirectionalLight {
  ambientIntensity 1
  direction -0.33 -1 -0.5
  castShadows TRUE
}
DEF WATER Fluid {
  translation 0 -0.4 0
  children [
    DEF WATER_BOX Shape {
      appearance Appearance {
        material Material {
          diffuseColor 0 0.498039 1
          transparency 0.7
        }
      }
      geometry Box {
        size 12 0.8 10
      }
    }
  ]
  boundingObject USE WATER_BOX
  locked TRUE
}
Floor {
  translation 0 -0.8 0
  size 12 8
  texture [
    "textures/rock.jpg"
  ]
}
DEF ICECRUST Solid {
  translation -0.62 0.332199 -2.80022
  rotation 1 0 0 2.87979
  children [
    DEF ICE_BOX Shape {
      appearance Appearance {
        material Material {
          diffuseColor 0 0.498039 1
        }
        texture ImageTexture {
          url [
            "Europa_Ice_Rafts.jpg"
          ]
        }
      }
      geometry Box {
        size 4 1.5 2.5
      }
    }
  ]
  boundingObject USE ICE_BOX
}
DEF ICECRUST Solid {
  translation -3.7 0.275 -5.27
  children [
    DEF ICE_BOX Shape {
      appearance Appearance {
        material Material {
          diffuseColor 0 0.498039 1
        }
        texture ImageTexture {
          url [
            "Europa_Ice_Rafts.jpg"
          ]
        }
      }
      geometry Box {
        size 4 1 8
      }
    }
  ]
  boundingObject USE ICE_BOX
}
DEF ICECRUST Solid {
  translation -0.25 0.39 0.19
  rotation 0 0 1 3.40339
  children [
    DEF ICE_BOX Shape {
      appearance Appearance {
        material Material {
          diffuseColor 0 0.498039 1
        }
        texture ImageTexture {
          url [
            "Europa_Ice_Rafts.jpg"
          ]
        }
      }
      geometry Box {
        size 3 1.5 4
      }
    }
  ]
  boundingObject USE ICE_BOX
}
DEF ICECRUST Solid {
  translation 3.5 0.5 -1
  children [
    DEF ICE_BOX Shape {
      appearance Appearance {
        material Material {
          diffuseColor 0 0.498039 1
        }
        texture ImageTexture {
          url [
            "Europa_Ice_Rafts.jpg"
          ]
        }
      }
      geometry Box {
        size 5 2 6
      }
    }
  ]
  boundingObject USE ICE_BOX
}
DEF SALAMANDER Robot {
  translation 4.60998 1.63422 -1.61
  rotation 0 1 0 1.5708
  children [
    GPS {
    }
    DEF SMALL_SEGMENT Group {
      children [
        Transform {
          children [
            Shape {
              appearance DEF SALAMANDER_COLOR Appearance {
                material Material {
                  ambientIntensity 0.3
                  diffuseColor 1 0.8 0.3
                  shininess 0.6
                  specularColor 1 0.909804 0.678431
                }
              }
              geometry Cylinder {
                height 0.0561
                radius 0.019
              }
            }
          ]
        }
        Transform {
          translation 0 0 0.038
          children [
            Shape {
              appearance USE SALAMANDER_COLOR
              geometry Box {
                size 0.038 0.056 0.076
              }
            }
          ]
        }
      ]
    }
    DEF LEFT_EYE DistanceSensor {
      translation -0.02 0.03 0
      rotation 0 1 0 2.356
      children [
        DEF EYE_SHAPE Shape {
          appearance DEF EYE_APPEARANCE Appearance {
            material Material {
              diffuseColor 0.2 0.2 0.2
              shininess 0.8
              specularColor 1 1 1
            }
          }
          geometry Sphere {
            radius 0.005
            subdivision 2
          }
        }
      ]
      name "ds_left"
      lookupTable [
        0 0 0
        0.7 0.7 0
      ]
      numberOfRays 6
      aperture 0.8
    }
    DEF RIGHT_EYE DistanceSensor {
      translation 0.02 0.03 0
      rotation 0 1 0 0.785
      children [
        USE EYE_SHAPE
      ]
      name "ds_right"
      lookupTable [
        0 0 0
        0.7 0.7 0
      ]
      numberOfRays 6
      aperture 0.8
    }
    DEF HINGE_JOINT_1 HingeJoint {
      jointParameters HingeJointParameters {
        axis 0 1 0
        anchor 0 0 0.108
      }
      device [
        RotationalMotor {
          name "motor_1"
          minPosition -0.0001
          maxPosition 0.0001
          maxTorque 100
        }
      ]
      endPoint DEF SOLID_1 Solid {
        translation 0 0 0.108
        children [
          DEF BIG_SEGMENT Group {
            children [
              Transform {
                children [
                  Shape {
                    appearance USE SALAMANDER_COLOR
                    geometry Cylinder {
                      height 0.0561
                      radius 0.032
                    }
                  }
                ]
              }
              Transform {
                translation 0 0 0.0235
                children [
                  Shape {
                    appearance USE SALAMANDER_COLOR
                    geometry Box {
                      size 0.064 0.056 0.047
                    }
                  }
                ]
              }
            ]
          }
          DEF HINGE_JOINT_LEG_1 HingeJoint {
            jointParameters HingeJointParameters {
              anchor -0.032 0 0.02
            }
            device [
              RotationalMotor {
                name "motor_leg_1"
                maxVelocity 20
                maxTorque 100
              }
            ]
            endPoint DEF SOLID_LEG_1 Solid {
              translation -0.032 0 0.02
              rotation 1 0 0 0
              children [
                DEF GROUP_FEMUR_1 Group {
                  children [
                    DEF TRANSFORM_HIP_1 Transform {
                      translation -0.004 0 0
                      rotation 0 0 1 1.5708
                      children [
                        DEF SHAPE_HIP Shape {
                          appearance DEF LEG_COLOR Appearance {
                            material Material {
                              diffuseColor 0.2 0.2 0.2
                              shininess 0.8
                              specularColor 1 1 1
                            }
                          }
                          geometry Cylinder {
                            height 0.008
                            radius 0.00975
                          }
                        }
                      ]
                    }
                    DEF TRANSFORM_FEMUR_1 Transform {
                      translation -0.016 0 0
                      rotation 0 0 1 1.5708
                      children [
                        DEF FEMUR Shape {
                          appearance USE LEG_COLOR
                          geometry Capsule {
                            height 0.016
                            radius 0.00575
                          }
                        }
                      ]
                    }
                  ]
                }
                DEF SERVO_TIBIA_1 Solid {
                  translation -0.024 0 0
                  rotation 0 0 1 1.0472
                  children [
                    DEF GROUP_TIBIA_1 Group {
                      children [
                        DEF TRANSFORM_TIBIA_1 Transform {
                          translation -0.0225 0 0
                          rotation 0 0 1 1.5708
                          children [
                            DEF TIBIA Shape {
                              appearance USE LEG_COLOR
                              geometry Capsule {
                                height 0.042
                                radius 0.00575
                              }
                            }
                          ]
                        }
                        DEF TRANSFORM_FOOT_1 Transform {
                          translation -0.045 -0.002 -0.0055
                          rotation 0 0 1 -1.0472
                          children [
                            DEF FOOT Shape {
                              appearance USE LEG_COLOR
                              geometry Cylinder {
                                height 0.0075
                                radius 0.013
                              }
                            }
                          ]
                        }
                      ]
                    }
                  ]
                  contactMaterial "leg"
                  immersionProperties [
                    DEF IMMERSION_PROP_TIBIA ImmersionProperties {
                      fluidName "fluid"
                      dragForceCoefficients 0.95 0.15 0.15
                    }
                  ]
                  boundingObject USE GROUP_TIBIA_1
                  physics Physics {
                    density -1
                    mass 0.0045704
                    centerOfMass [
                      -0.03 0 0
                    ]
                    inertiaMatrix [
                      2.59057e-07 1.32103e-06 1.25007e-06
                      -2.73481e-08 -1.64256e-07 -2.19008e-08
                    ]
                  }
                }
              ]
              contactMaterial "body"
              immersionProperties [
                DEF IMMERSION_PROP_FEMUR ImmersionProperties {
                  fluidName "fluid"
                  dragForceCoefficients 0 0.15 0.15
                }
              ]
              boundingObject USE GROUP_FEMUR_1
              physics Physics {
                density -1
                mass 0.00242371
                centerOfMass [
                  -0.012 0 0
                ]
                inertiaMatrix [
                  7.57828e-08 1.99961e-07 1.99961e-07
                  -1.03066e-13 0 0
                ]
              }
            }
          }
          DEF HINGE_JOINT_LEG_2 HingeJoint {
            jointParameters HingeJointParameters {
              anchor 0.032 0 0.02
            }
            device [
              RotationalMotor {
                name "motor_leg_2"
                maxVelocity 20
                maxTorque 100
              }
            ]
            endPoint DEF SOLID_LEG_2 Solid {
              translation 0.032 0 0.02
              rotation 1 0 0 3.14159
              children [
                DEF GROUP_FEMUR_2 Group {
                  children [
                    DEF TRANSFORM_HIP_2 Transform {
                      translation 0.004 0 0
                      rotation 0 0 1 1.5708
                      children [
                        USE SHAPE_HIP
                      ]
                    }
                    DEF TRANSFORM_FEMUR_2 Transform {
                      translation 0.016 0 0
                      rotation 0 0 1 1.5708
                      children [
                        DEF FEMUR Shape {
                          appearance USE LEG_COLOR
                          geometry Capsule {
                            height 0.016
                            radius 0.00575
                          }
                        }
                      ]
                    }
                  ]
                }
                DEF SERVO_TIBIA_2 Solid {
                  translation 0.024 0 0
                  rotation 0 0 1 1.0472
                  children [
                    DEF GROUP_TIBIA_2 Group {
                      children [
                        DEF TRANSFORM_TIBIA_2 Transform {
                          translation 0.0225 0 0
                          rotation 0 0 1 1.5708
                          children [
                            DEF TIBIA Shape {
                              appearance USE LEG_COLOR
                              geometry Capsule {
                                height 0.042
                                radius 0.00575
                              }
                            }
                          ]
                        }
                        DEF TRANSFORM_FOOT_2 Transform {
                          translation 0.045 0.002 0.0055
                          rotation 0 0 1 -1.0472
                          children [
                            DEF FOOT Shape {
                              appearance USE LEG_COLOR
                              geometry Cylinder {
                                height 0.0075
                                radius 0.013
                              }
                            }
                          ]
                        }
                      ]
                    }
                  ]
                  contactMaterial "leg"
                  immersionProperties [
                    USE IMMERSION_PROP_TIBIA
                  ]
                  boundingObject USE GROUP_TIBIA_2
                  physics Physics {
                    density -1
                    mass 0.0045704
                    centerOfMass [
                      0.03 0 0
                    ]
                    inertiaMatrix [
                      2.59057e-07 1.32103e-06 1.25007e-06
                      -2.73481e-08 -1.64256e-07 -2.19008e-08
                    ]
                  }
                }
              ]
              contactMaterial "body"
              immersionProperties [
                USE IMMERSION_PROP_FEMUR
              ]
              boundingObject USE GROUP_FEMUR_2
              physics Physics {
                density -1
                mass 0.00242371
                centerOfMass [
                  0.012 0 0
                ]
                inertiaMatrix [
                  7.57828e-08 1.99961e-07 1.99961e-07
                  -1.03066e-13 0 0
                ]
              }
            }
          }
          DEF HINGE_JOINT_2 HingeJoint {
            jointParameters HingeJointParameters {
              axis 0 1 0
              anchor 0 0 0.066
            }
            device [
              RotationalMotor {
                name "motor_2"
                minPosition -1.13446
                maxPosition 1.13446
                maxTorque 100
              }
            ]
            endPoint DEF SOLID_2 Solid {
              translation 0 0 0.066
              children [
                USE SMALL_SEGMENT
                DEF HINGE_JOINT_3 HingeJoint {
                  jointParameters HingeJointParameters {
                    axis 0 1 0
                    anchor 0 0 0.095
                  }
                  device [
                    RotationalMotor {
                      name "motor_3"
                      minPosition -1.13446
                      maxPosition 1.13446
                      maxTorque 100
                    }
                  ]
                  endPoint DEF SOLID_3 Solid {
                    translation 0 0 0.095
                    children [
                      USE SMALL_SEGMENT
                      DEF HINGE_JOINT_4 HingeJoint {
                        jointParameters HingeJointParameters {
                          axis 0 1 0
                          anchor 0 0 0.095
                        }
                        device [
                          RotationalMotor {
                            name "motor_4"
                            minPosition -1.13446
                            maxPosition 1.13446
                            maxTorque 100
                          }
                        ]
                        endPoint DEF SOLID_4 Solid {
                          translation 0 0 0.095
                          children [
                            USE SMALL_SEGMENT
                            DEF HINGE_JOINT_5 HingeJoint {
                              jointParameters HingeJointParameters {
                                axis 0 1 0
                                anchor 0 0 0.108
                              }
                              device [
                                RotationalMotor {
                                  name "motor_5"
                                  minPosition -0.0001
                                  maxPosition 0.0001
                                  maxTorque 100
                                }
                              ]
                              endPoint DEF SOLID_5 Solid {
                                translation 0 0 0.108
                                children [
                                  USE BIG_SEGMENT
                                  DEF HINGE_JOINT_LEG_3 HingeJoint {
                                    jointParameters HingeJointParameters {
                                      anchor -0.032 0 0.02
                                    }
                                    device [
                                      RotationalMotor {
                                        name "motor_leg_3"
                                        maxVelocity 20
                                        maxTorque 100
                                      }
                                    ]
                                    endPoint DEF SOLID_LEG_3 Solid {
                                      translation -0.032 0 0.02
                                      rotation 1 0 0 0
                                      children [
                                        DEF GROUP_FEMUR_3 Group {
                                          children [
                                            DEF TRANSFORM_HIP_3 Transform {
                                              translation -0.004 0 0
                                              rotation 0 0 1 1.5708
                                              children [
                                                USE SHAPE_HIP
                                              ]
                                            }
                                            DEF TRANSFORM_FEMUR_3 Transform {
                                              translation -0.016 0 0
                                              rotation 0 0 1 1.5708
                                              children [
                                                DEF FEMUR Shape {
                                                  appearance USE LEG_COLOR
                                                  geometry Capsule {
                                                    height 0.016
                                                    radius 0.00575
                                                  }
                                                }
                                              ]
                                            }
                                          ]
                                        }
                                        DEF SERVO_TIBIA_3 Solid {
                                          translation -0.024 0 0
                                          rotation 0 0 1 1.0472
                                          children [
                                            DEF GROUP_TIBIA_3 Group {
                                              children [
                                                DEF TRANSFORM_TIBIA_3 Transform {
                                                  translation -0.0225 0 0
                                                  rotation 0 0 1 1.5708
                                                  children [
                                                    DEF TIBIA Shape {
                                                      appearance USE LEG_COLOR
                                                      geometry Capsule {
                                                        height 0.042
                                                        radius 0.00575
                                                      }
                                                    }
                                                  ]
                                                }
                                                DEF TRANSFORM_FOOT_3 Transform {
                                                  translation -0.045 -0.002 -0.0055
                                                  rotation 0 0 1 -1.0472
                                                  children [
                                                    DEF FOOT Shape {
                                                      appearance USE LEG_COLOR
                                                      geometry Cylinder {
                                                        height 0.0075
                                                        radius 0.013
                                                      }
                                                    }
                                                  ]
                                                }
                                              ]
                                            }
                                          ]
                                          contactMaterial "leg"
                                          immersionProperties [
                                            USE IMMERSION_PROP_TIBIA
                                          ]
                                          boundingObject USE GROUP_TIBIA_3
                                          physics Physics {
                                            density -1
                                            mass 0.0045704
                                            centerOfMass [
                                              -0.03 0 0
                                            ]
                                            inertiaMatrix [
                                              2.59057e-07 1.32103e-06 1.25007e-06
                                              -2.73481e-08 -1.64256e-07 -2.19008e-08
                                            ]
                                          }
                                        }
                                      ]
                                      contactMaterial "body"
                                      immersionProperties [
                                        USE IMMERSION_PROP_FEMUR
                                      ]
                                      boundingObject USE GROUP_FEMUR_3
                                      physics Physics {
                                        density -1
                                        mass 0.00242371
                                        centerOfMass [
                                          -0.012 0 0
                                        ]
                                        inertiaMatrix [
                                          7.57828e-08 1.99961e-07 1.99961e-07
                                          -1.03066e-13 0 0
                                        ]
                                      }
                                    }
                                  }
                                  DEF HINGE_JOINT_LEG_4 HingeJoint {
                                    jointParameters HingeJointParameters {
                                      anchor 0.032 0 0.02
                                    }
                                    device [
                                      RotationalMotor {
                                        name "motor_leg_4"
                                        maxVelocity 20
                                        maxTorque 100
                                      }
                                    ]
                                    endPoint DEF SOLID_LEG_4 Solid {
                                      translation 0.032 0 0.02
                                      rotation 1 0 0 3.14159
                                      children [
                                        DEF GROUP_FEMUR_4 Group {
                                          children [
                                            DEF TRANSFORM_HIP_4 Transform {
                                              translation 0.004 0 0
                                              rotation 0 0 1 1.5708
                                              children [
                                                USE SHAPE_HIP
                                              ]
                                            }
                                            DEF TRANSFORM_FEMUR_4 Transform {
                                              translation 0.016 0 0
                                              rotation 0 0 1 1.5708
                                              children [
                                                DEF FEMUR Shape {
                                                  appearance USE LEG_COLOR
                                                  geometry Capsule {
                                                    height 0.016
                                                    radius 0.00575
                                                  }
                                                }
                                              ]
                                            }
                                          ]
                                        }
                                        DEF SERVO_TIBIA_4 Solid {
                                          translation 0.024 0 0
                                          rotation 0 0 1 1.0472
                                          children [
                                            DEF GROUP_TIBIA_4 Group {
                                              children [
                                                DEF TRANSFORM_TIBIA_4 Transform {
                                                  translation 0.0225 0 0
                                                  rotation 0 0 1 1.5708
                                                  children [
                                                    DEF TIBIA Shape {
                                                      appearance USE LEG_COLOR
                                                      geometry Capsule {
                                                        height 0.042
                                                        radius 0.00575
                                                      }
                                                    }
                                                  ]
                                                }
                                                DEF TRANSFORM_FOOT_4 Transform {
                                                  translation 0.045 0.002 0.0055
                                                  rotation 0 0 1 -1.0472
                                                  children [
                                                    DEF FOOT Shape {
                                                      appearance USE LEG_COLOR
                                                      geometry Cylinder {
                                                        height 0.0075
                                                        radius 0.013
                                                      }
                                                    }
                                                  ]
                                                }
                                              ]
                                            }
                                          ]
                                          contactMaterial "leg"
                                          immersionProperties [
                                            USE IMMERSION_PROP_TIBIA
                                          ]
                                          boundingObject USE GROUP_TIBIA_4
                                          physics Physics {
                                            density -1
                                            mass 0.0045704
                                            centerOfMass [
                                              0.03 0 0
                                            ]
                                            inertiaMatrix [
                                              2.59057e-07 1.32103e-06 1.25007e-06
                                              -2.73481e-08 -1.64256e-07 -2.19008e-08
                                            ]
                                          }
                                        }
                                      ]
                                      contactMaterial "body"
                                      immersionProperties [
                                        USE IMMERSION_PROP_FEMUR
                                      ]
                                      boundingObject USE GROUP_FEMUR_4
                                      physics Physics {
                                        density -1
                                        mass 0.00242371
                                        centerOfMass [
                                          0.012 0 0
                                        ]
                                        inertiaMatrix [
                                          7.57828e-08 1.99961e-07 1.99961e-07
                                          -1.03066e-13 0 0
                                        ]
                                      }
                                    }
                                  }
                                  DEF HINGE_JOINT_6 HingeJoint {
                                    jointParameters HingeJointParameters {
                                      axis 0 1 0
                                      anchor 0 0 0.066
                                    }
                                    device [
                                      RotationalMotor {
                                        name "motor_6"
                                        minPosition -1.13446
                                        maxPosition 1.13446
                                        maxTorque 100
                                      }
                                    ]
                                    endPoint DEF SOLID_6 Solid {
                                      translation 0 0 0.066
                                      children [
                                        USE SMALL_SEGMENT
                                        DEF HINGE_JOINT_7 HingeJoint {
                                          jointParameters HingeJointParameters {
                                            axis 0 1 0
                                            anchor 0 0 0.095
                                          }
                                          device [
                                            RotationalMotor {
                                              name "motor_7"
                                              minPosition -1.13446
                                              maxPosition 1.13446
                                              maxTorque 100
                                            }
                                          ]
                                          endPoint DEF SOLID_7 Solid {
                                            translation 0 0 0.095
                                            children [
                                              USE SMALL_SEGMENT
                                              DEF HINGE_JOINT_8 HingeJoint {
                                                jointParameters HingeJointParameters {
                                                  axis 0 1 0
                                                  anchor 0 0 0.095
                                                }
                                                device [
                                                  RotationalMotor {
                                                    name "motor_8"
                                                    minPosition -1.13446
                                                    maxPosition 1.13446
                                                    maxTorque 100
                                                  }
                                                ]
                                                endPoint DEF SOLID_8 Solid {
                                                  translation 0 0 0.095
                                                  children [
                                                    USE SMALL_SEGMENT
                                                  ]
                                                  contactMaterial "body"
                                                  immersionProperties [
                                                    DEF IMMERSION_PROP_SEGMENT ImmersionProperties {
                                                      fluidName "fluid"
                                                      referenceArea "xyz-projection"
                                                      dragForceCoefficients 3.1 1.3 0
                                                      viscousResistanceTorqueCoefficient 5
                                                    }
                                                  ]
                                                  boundingObject USE SMALL_SEGMENT
                                                  physics DEF SEGMENT_PHYSICS Physics {
                                                    density -1
                                                    mass 0.180281
                                                    centerOfMass [
                                                      0 -0.014 0.038
                                                    ]
                                                    inertiaMatrix [
                                                      0.000222864 0.000160531 0.000102659
                                                      0 0 2.70783e-05
                                                    ]
                                                  }
                                                }
                                              }
                                            ]
                                            contactMaterial "body"
                                            immersionProperties [
                                              USE IMMERSION_PROP_SEGMENT
                                            ]
                                            boundingObject USE SMALL_SEGMENT
                                            physics USE SEGMENT_PHYSICS
                                          }
                                        }
                                      ]
                                      contactMaterial "body"
                                      immersionProperties [
                                        USE IMMERSION_PROP_SEGMENT
                                      ]
                                      boundingObject USE SMALL_SEGMENT
                                      physics USE SEGMENT_PHYSICS
                                    }
                                  }
                                ]
                                contactMaterial "body"
                                immersionProperties [
                                  USE IMMERSION_PROP_SEGMENT
                                ]
                                boundingObject USE BIG_SEGMENT
                                physics DEF BIG_SEGMENT_PHYSICS Physics {
                                  density -1
                                  mass 0.279137
                                  centerOfMass [
                                    0 -0.014 0.0235
                                  ]
                                  inertiaMatrix [
                                    0.000269294 0.000224459 0.000210752
                                    0 0 4.75005e-05
                                  ]
                                }
                              }
                            }
                          ]
                          contactMaterial "body"
                          immersionProperties [
                            USE IMMERSION_PROP_SEGMENT
                          ]
                          boundingObject USE SMALL_SEGMENT
                          physics USE SEGMENT_PHYSICS
                        }
                      }
                    ]
                    contactMaterial "body"
                    immersionProperties [
                      USE IMMERSION_PROP_SEGMENT
                    ]
                    boundingObject USE SMALL_SEGMENT
                    physics USE SEGMENT_PHYSICS
                  }
                }
              ]
              contactMaterial "body"
              immersionProperties [
                DEF IMMERSION_PROP_SEGMENT_2 ImmersionProperties {
                  fluidName "fluid"
                  referenceArea "xyz-projection"
                  dragForceCoefficients 1.75 0.95 0.5
                  viscousResistanceTorqueCoefficient 5
                }
              ]
              boundingObject USE SMALL_SEGMENT
              physics USE SEGMENT_PHYSICS
            }
          }
        ]
        contactMaterial "body"
        immersionProperties [
          DEF IMMERSION_PROP_SEGMENT_1 ImmersionProperties {
            fluidName "fluid"
            referenceArea "xyz-projection"
            dragForceCoefficients 1.8 0.95 0.75
            viscousResistanceTorqueCoefficient 5
          }
        ]
        boundingObject USE BIG_SEGMENT
        physics USE BIG_SEGMENT_PHYSICS
      }
    }
  ]
  name "salamander"
  contactMaterial "body"
  immersionProperties [
    DEF IMMERSION_PROP_SALAMANDER ImmersionProperties {
      fluidName "fluid"
      referenceArea "xyz-projection"
      dragForceCoefficients 2 1 1
      viscousResistanceTorqueCoefficient 5
    }
  ]
  boundingObject USE SMALL_SEGMENT
  physics USE SEGMENT_PHYSICS
  controller "salamander"
}
DEF MODULE_1 Robot {
  translation 0 1.3 0
  rotation 0 0 1 1.5708
  children [
    DEF BODY_GROUP Group {
      children [
        DEF BOX_SHAPE Shape {
          appearance DEF PLASTIC Appearance {
            material Material {
              diffuseColor 0 1 0
            }
          }
          geometry Box {
            size 0.054 0.0482 0.06
          }
        }
        DEF CYLINDER_TRANS Transform {
          translation 0 0 -0.03
          children [
            Shape {
              appearance USE PLASTIC
              geometry Cylinder {
                height 0.0482
                radius 0.027
              }
            }
          ]
        }
      ]
    }
    DEF REAR_CONNECTOR Connector {
      translation 0 0 0.03
      children [
        DEF ROUND_SHAPE Transform {
          rotation 1 0 0 1.5708
          children [
            Shape {
              appearance Appearance {
                material Material {
                  diffuseColor 1 1 1
                }
              }
              geometry Cylinder {
                height 0.0005
                radius 0.0075
              }
            }
          ]
        }
      ]
      name "rear_connector"
      isLocked TRUE
      distanceTolerance 0.05
      axisTolerance 0.5
      rotationTolerance 0.5
    }
    DEF HINGE_JOINT HingeJoint {
      jointParameters HingeJointParameters {
        axis 0 1 0
        anchor 0 0 -0.03
      }
      device [
        RotationalMotor {
          name "motor"
          maxVelocity 3.9667
          minPosition -1.5708
          maxPosition 1.5708
          maxTorque 1.1
        }
      ]
      endPoint Solid {
        translation 0 0 -0.03
        children [
          DEF GREY_BOX_TRANS Transform {
            translation 0 0 -0.0135
            children [
              Shape {
                appearance Appearance {
                  material Material {
                    diffuseColor 0.752941 0.752941 0.752941
                  }
                }
                geometry Box {
                  size 0.015 0.0612 0.047
                }
              }
            ]
          }
          DEF FRONT_CONNECTOR Connector {
            translation 0 0 -0.037
            rotation 0 1 0 3.1416
            children [
              USE ROUND_SHAPE
            ]
            name "front_connector"
            isLocked TRUE
            distanceTolerance 0.05
            axisTolerance 0.5
            rotationTolerance 0.5
          }
        ]
        boundingObject USE GREY_BOX_TRANS
        physics Physics {
          density -1
          mass 0.016
        }
      }
    }
  ]
  name "module_1"
  boundingObject USE BODY_GROUP
  physics DEF BODY_PHYSICS Physics {
    density -1
    mass 0.17
  }
  controller "yamor"
}
DEF MODULE_2 Robot {
  translation 0 1.3 0.097
  rotation 0 0 1 1.5708
  children [
    USE BODY_GROUP
    DEF REAR_CONNECTOR Connector {
      translation 0 0 0.03
      children [
        DEF ROUND_SHAPE Transform {
          rotation 1 0 0 1.5708
          children [
            Shape {
              appearance Appearance {
                material Material {
                  diffuseColor 1 1 1
                }
              }
              geometry Cylinder {
                height 0.0005
                radius 0.0075
              }
            }
          ]
        }
      ]
      name "rear_connector"
      isLocked TRUE
      distanceTolerance 0.05
      axisTolerance 0.5
      rotationTolerance 0.5
    }
    DEF HINGE_JOINT HingeJoint {
      jointParameters HingeJointParameters {
        axis 0 1 0
        anchor 0 0 -0.03
      }
      device [
        RotationalMotor {
          name "motor"
          maxVelocity 3.9667
          minPosition -1.5708
          maxPosition 1.5708
          maxTorque 1.1
        }
      ]
      endPoint Solid {
        translation 0 0 -0.03
        children [
          DEF GREY_BOX_TRANS Transform {
            translation 0 0 -0.0135
            children [
              Shape {
                appearance Appearance {
                  material Material {
                    diffuseColor 0.752941 0.752941 0.752941
                  }
                }
                geometry Box {
                  size 0.015 0.0612 0.047
                }
              }
            ]
          }
          DEF FRONT_CONNECTOR Connector {
            translation 0 0 -0.037
            rotation 0 1 0 3.1416
            children [
              USE ROUND_SHAPE
            ]
            name "front_connector"
            isLocked TRUE
            distanceTolerance 0.05
            axisTolerance 0.5
            rotationTolerance 0.5
          }
        ]
        boundingObject USE GREY_BOX_TRANS
        physics Physics {
          density -1
          mass 0.016
        }
      }
    }
  ]
  name "module_2"
  boundingObject USE BODY_GROUP
  physics USE BODY_PHYSICS
  controller "yamor"
}
DEF MODULE_3 Robot {
  translation 0 1.3 0.194
  rotation 0 0 1 1.5708
  children [
    USE BODY_GROUP
    DEF REAR_CONNECTOR Connector {
      translation 0 0 0.03
      children [
        DEF ROUND_SHAPE Transform {
          rotation 1 0 0 1.5708
          children [
            Shape {
              appearance Appearance {
                material Material {
                  diffuseColor 1 1 1
                }
              }
              geometry Cylinder {
                height 0.0005
                radius 0.0075
              }
            }
          ]
        }
      ]
      name "rear_connector"
      isLocked TRUE
      distanceTolerance 0.05
      axisTolerance 0.5
      rotationTolerance 0.5
    }
    DEF HINGE_JOINT HingeJoint {
      jointParameters HingeJointParameters {
        axis 0 1 0
        anchor 0 0 -0.03
      }
      device [
        RotationalMotor {
          name "motor"
          maxVelocity 3.9667
          minPosition -1.5708
          maxPosition 1.5708
          maxTorque 1.1
        }
      ]
      endPoint Solid {
        translation 0 0 -0.03
        children [
          DEF GREY_BOX_TRANS Transform {
            translation 0 0 -0.0135
            children [
              Shape {
                appearance Appearance {
                  material Material {
                    diffuseColor 0.752941 0.752941 0.752941
                  }
                }
                geometry Box {
                  size 0.015 0.0612 0.047
                }
              }
            ]
          }
          DEF FRONT_CONNECTOR Connector {
            translation 0 0 -0.037
            rotation 0 1 0 3.1416
            children [
              USE ROUND_SHAPE
            ]
            name "front_connector"
            isLocked TRUE
            distanceTolerance 0.05
            axisTolerance 0.5
            rotationTolerance 0.5
          }
        ]
        boundingObject USE GREY_BOX_TRANS
        physics Physics {
          density -1
          mass 0.016
        }
      }
    }
  ]
  name "module_3"
  boundingObject USE BODY_GROUP
  physics USE BODY_PHYSICS
  controller "yamor"
}
DEF MODULE_4 Robot {
  translation 0 1.3 0.291
  rotation 0 0 1 1.5708
  children [
    USE BODY_GROUP
    DEF REAR_CONNECTOR Connector {
      translation 0 0 0.03
      children [
        DEF ROUND_SHAPE Transform {
          rotation 1 0 0 1.5708
          children [
            Shape {
              appearance Appearance {
                material Material {
                  diffuseColor 1 1 1
                }
              }
              geometry Cylinder {
                height 0.0005
                radius 0.0075
              }
            }
          ]
        }
      ]
      name "rear_connector"
      isLocked TRUE
      distanceTolerance 0.05
      axisTolerance 0.5
      rotationTolerance 0.5
    }
    DEF HINGE_JOINT HingeJoint {
      jointParameters HingeJointParameters {
        axis 0 1 0
        anchor 0 0 -0.03
      }
      device [
        RotationalMotor {
          name "motor"
          maxVelocity 3.9667
          minPosition -1.5708
          maxPosition 1.5708
          maxTorque 1.1
        }
      ]
      endPoint Solid {
        translation 0 0 -0.03
        children [
          DEF GREY_BOX_TRANS Transform {
            translation 0 0 -0.0135
            children [
              Shape {
                appearance Appearance {
                  material Material {
                    diffuseColor 0.752941 0.752941 0.752941
                  }
                }
                geometry Box {
                  size 0.015 0.0612 0.047
                }
              }
            ]
          }
          DEF FRONT_CONNECTOR Connector {
            translation 0 0 -0.037
            rotation 0 1 0 3.1416
            children [
              USE ROUND_SHAPE
            ]
            name "front_connector"
            isLocked TRUE
            distanceTolerance 0.05
            axisTolerance 0.5
            rotationTolerance 0.5
          }
        ]
        boundingObject USE GREY_BOX_TRANS
        physics Physics {
          density -1
          mass 0.016
        }
      }
    }
  ]
  name "module_4"
  boundingObject USE BODY_GROUP
  physics USE BODY_PHYSICS
  controller "yamor"
}
DEF MODULE_5 Robot {
  translation 0 1.3 0.388
  rotation 0 0 1 1.5708
  children [
    USE BODY_GROUP
    DEF REAR_CONNECTOR Connector {
      translation 0 0 0.03
      children [
        DEF ROUND_SHAPE Transform {
          rotation 1 0 0 1.5708
          children [
            Shape {
              appearance Appearance {
                material Material {
                  diffuseColor 1 1 1
                }
              }
              geometry Cylinder {
                height 0.0005
                radius 0.0075
              }
            }
          ]
        }
      ]
      name "rear_connector"
      isLocked TRUE
      distanceTolerance 0.05
      axisTolerance 0.5
      rotationTolerance 0.5
    }
    DEF HINGE_JOINT HingeJoint {
      jointParameters HingeJointParameters {
        axis 0 1 0
        anchor 0 0 -0.03
      }
      device [
        RotationalMotor {
          name "motor"
          maxVelocity 3.9667
          minPosition -1.5708
          maxPosition 1.5708
          maxTorque 1.1
        }
      ]
      endPoint Solid {
        translation 0 0 -0.03
        children [
          DEF GREY_BOX_TRANS Transform {
            translation 0 0 -0.0135
            children [
              Shape {
                appearance Appearance {
                  material Material {
                    diffuseColor 0.752941 0.752941 0.752941
                  }
                }
                geometry Box {
                  size 0.015 0.0612 0.047
                }
              }
            ]
          }
          DEF FRONT_CONNECTOR Connector {
            translation 0 0 -0.037
            rotation 0 1 0 3.1416
            children [
              USE ROUND_SHAPE
            ]
            name "front_connector"
            isLocked TRUE
            distanceTolerance 0.05
            axisTolerance 0.5
            rotationTolerance 0.5
          }
        ]
        boundingObject USE GREY_BOX_TRANS
        physics Physics {
          density -1
          mass 0.016
        }
      }
    }
  ]
  name "module_5"
  boundingObject USE BODY_GROUP
  physics USE BODY_PHYSICS
  controller "yamor"
}
DEF MODULE_6 Robot {
  translation 0 1.3 0.485
  rotation 0 0 1 1.5708
  children [
    USE BODY_GROUP
    DEF REAR_CONNECTOR Connector {
      translation 0 0 0.03
      children [
        DEF ROUND_SHAPE Transform {
          rotation 1 0 0 1.5708
          children [
            Shape {
              appearance Appearance {
                material Material {
                  diffuseColor 1 1 1
                }
              }
              geometry Cylinder {
                height 0.0005
                radius 0.0075
              }
            }
          ]
        }
      ]
      name "rear_connector"
      isLocked TRUE
      distanceTolerance 0.05
      axisTolerance 0.5
      rotationTolerance 0.5
    }
    DEF HINGE_JOINT HingeJoint {
      jointParameters HingeJointParameters {
        axis 0 1 0
        anchor 0 0 -0.03
      }
      device [
        RotationalMotor {
          name "motor"
          maxVelocity 3.9667
          minPosition -1.5708
          maxPosition 1.5708
          maxTorque 1.1
        }
      ]
      endPoint Solid {
        translation 0 0 -0.03
        children [
          DEF GREY_BOX_TRANS Transform {
            translation 0 0 -0.0135
            children [
              Shape {
                appearance Appearance {
                  material Material {
                    diffuseColor 0.752941 0.752941 0.752941
                  }
                }
                geometry Box {
                  size 0.015 0.0612 0.047
                }
              }
            ]
          }
          DEF FRONT_CONNECTOR Connector {
            translation 0 0 -0.037
            rotation 0 1 0 3.1416
            children [
              USE ROUND_SHAPE
            ]
            name "front_connector"
            isLocked TRUE
            distanceTolerance 0.05
            axisTolerance 0.5
            rotationTolerance 0.5
          }
        ]
        boundingObject USE GREY_BOX_TRANS
        physics Physics {
          density -1
          mass 0.016
        }
      }
    }
  ]
  name "module_6"
  boundingObject USE BODY_GROUP
  physics USE BODY_PHYSICS
  controller "yamor"
}
DEF MODULE_7 Robot {
  translation 0 1.3 0.582
  rotation 0 0 1 1.5708
  children [
    USE BODY_GROUP
    DEF REAR_CONNECTOR Connector {
      translation 0 0 0.03
      children [
        DEF ROUND_SHAPE Transform {
          rotation 1 0 0 1.5708
          children [
            Shape {
              appearance Appearance {
                material Material {
                  diffuseColor 1 1 1
                }
              }
              geometry Cylinder {
                height 0.0005
                radius 0.0075
              }
            }
          ]
        }
      ]
      name "rear_connector"
      isLocked TRUE
      distanceTolerance 0.05
      axisTolerance 0.5
      rotationTolerance 0.5
    }
    DEF HINGE_JOINT HingeJoint {
      jointParameters HingeJointParameters {
        axis 0 1 0
        anchor 0 0 -0.03
      }
      device [
        RotationalMotor {
          name "motor"
          maxVelocity 3.9667
          minPosition -1.5708
          maxPosition 1.5708
          maxTorque 1.1
        }
      ]
      endPoint Solid {
        translation 0 0 -0.03
        children [
          DEF GREY_BOX_TRANS Transform {
            translation 0 0 -0.0135
            children [
              Shape {
                appearance Appearance {
                  material Material {
                    diffuseColor 0.752941 0.752941 0.752941
                  }
                }
                geometry Box {
                  size 0.015 0.0612 0.047
                }
              }
            ]
          }
          DEF FRONT_CONNECTOR Connector {
            translation 0 0 -0.037
            rotation 0 1 0 3.1416
            children [
              USE ROUND_SHAPE
            ]
            name "front_connector"
            isLocked TRUE
            distanceTolerance 0.05
            axisTolerance 0.5
            rotationTolerance 0.5
          }
        ]
        boundingObject USE GREY_BOX_TRANS
        physics Physics {
          density -1
          mass 0.016
        }
      }
    }
  ]
  name "module_7"
  boundingObject USE BODY_GROUP
  physics USE BODY_PHYSICS
  controller "yamor"
}
DEF MODULE_8 Robot {
  translation 0 1.3 0.679
  rotation 0 0 1 1.5708
  children [
    USE BODY_GROUP
    DEF REAR_CONNECTOR Connector {
      translation 0 0 0.03
      children [
        DEF ROUND_SHAPE Transform {
          rotation 1 0 0 1.5708
          children [
            Shape {
              appearance Appearance {
                material Material {
                  diffuseColor 1 1 1
                }
              }
              geometry Cylinder {
                height 0.0005
                radius 0.0075
              }
            }
          ]
        }
      ]
      name "rear_connector"
      isLocked TRUE
      distanceTolerance 0.05
      axisTolerance 0.5
      rotationTolerance 0.5
    }
    DEF HINGE_JOINT HingeJoint {
      jointParameters HingeJointParameters {
        axis 0 1 0
        anchor 0 0 -0.03
      }
      device [
        RotationalMotor {
          name "motor"
          maxVelocity 3.9667
          minPosition -1.5708
          maxPosition 1.5708
          maxTorque 1.1
        }
      ]
      endPoint Solid {
        translation 0 0 -0.03
        children [
          DEF GREY_BOX_TRANS Transform {
            translation 0 0 -0.0135
            children [
              Shape {
                appearance Appearance {
                  material Material {
                    diffuseColor 0.752941 0.752941 0.752941
                  }
                }
                geometry Box {
                  size 0.015 0.0612 0.047
                }
              }
            ]
          }
          DEF FRONT_CONNECTOR Connector {
            translation 0 0 -0.037
            rotation 0 1 0 3.1416
            children [
              USE ROUND_SHAPE
            ]
            name "front_connector"
            isLocked TRUE
            distanceTolerance 0.05
            axisTolerance 0.5
            rotationTolerance 0.5
          }
        ]
        boundingObject USE GREY_BOX_TRANS
        physics Physics {
          density -1
          mass 0.016
        }
      }
    }
  ]
  name "module_8"
  boundingObject USE BODY_GROUP
  physics USE BODY_PHYSICS
  controller "yamor"
}
